Workbook

Sheet API Endpoints
A1: Onshape API endpoints called by PLM
A2: Every outbound Onshape REST call the application makes, taken from src/lib/onshape/live-client.ts. Refs are used on the other sheets.
A4: Ref | B4: Client method | C4: HTTP | D4: Endpoint | E4: What it is for | F4: Caching | G4: Env override
A5: A1 | B5: getAuthenticatedUser | C5: GET | D5: /users/sessioninfo | E5: Identify the signed-in Onshape user; also supplies the enterprise vanity domain used to build links back into Onshape. | F5: None | G5: —
A6: A2 | B6: listPropertyDefinitions | C6: GET | D6: /metadataschema?ownerId={companyId}&ownerType=1&active=true | E6: Enumerate the enterprise's custom property definitions, so PLM attributes can be mapped to real Onshape property ids. | F6: 5 min, in-process | G6: ONSHAPE_METADATA_SCHEMA_PATH
A7: A3 | B7: getElementInfo | C7: GET | D7: /documents/d/{did}/{w|v}/{wvid}/elements?elementId={eid} | E7: Tab name and element type. Guards against treating a Part Studio, assembly or drawing as the wrong kind of thing. | F7: 5 min, in-process | G7: —
A8: A4 | B8: getDocumentInfo | C8: GET | D8: /documents/{did} | E8: Document name, default workspace, and whether the account may write to it. | F8: 5 min, in-process | G8: —
A9: A5 | B9: getDocumentInfo (fallback) | C9: GET | D9: /documents/d/{did}/workspaces | E9: Find a workspace when the document record does not name a default one. Conditional, so it has no process row of its own. | F9: Shares A4's cache entry | G9: —
A10: A6 | B10: listElementParts | C10: GET | D10: /parts/d/{did}/{w|v}/{wvid}/e/{eid} | E10: List the parts in an element — used to resolve a part number to a part id, and by the webhook path. | F10: None | G10: ONSHAPE_PARTS_PATH
A11: A7 | B11: getAssemblyBom | C11: GET | D11: /assemblies/d/{did}/{w|v}/{wvid}/e/{eid}/bom?indented=true&multiLevel=true | E11: The structured bill of materials. One call returns the WHOLE tree: indent level carries the hierarchy, so subassemblies cost no extra calls. | F11: None | G11: ONSHAPE_BOM_PATH
A12: A8 | B12: getPartMetadata | C12: GET | D12: /metadata/d/{did}/{w|v}/{wvid}/e/{eid}/p/{pid} | E12: Read every property on the part — the mirror read behind almost every sync. | F12: None | G12: —
A13: A9 | B13: updatePartProperties | C13: POST | D13: /metadata/d/{did}/{w|v}/{wvid}/e/{eid}/p/{pid} | E13: Write PLM's values back. Sent only for properties whose value differs, so a settled part costs nothing. | F13: None | G13: —
A14: A10 | B14: getPartThumbnail | C14: GET | D14: /parts|/assemblies/d/{did}/{w|v}/{wvid}/e/{eid}/shadedviews/… | E14: Render an image of the part or assembly. | F14: 7 days in MongoDB; 1 hr backoff after a failure | G14: ONSHAPE_SHADEDVIEWS_PATH / ONSHAPE_ASSEMBLY_SHADEDVIEWS_PATH
A15: A11 | B15: getMassProperties | C15: GET | D15: /partstudios|/assemblies/d/{did}/{w|v}/{wvid}/e/{eid}/massproperties | E15: Mass, volume, density and centre of mass. The mass is synced into PLM's Mass attribute. | F15: None | G15: ONSHAPE_MASSPROPERTIES_PATH / ONSHAPE_ASSEMBLY_MASSPROPERTIES_PATH
... A36: A32 | B36: deleteTask | C36: DELETE | D36: /tasks/{tid} | E36: Delete a task outright. Unpublished, and refused for most tasks — PLM falls back to the workflow's discard transition (A30). | F36: None | G36: ONSHAPE_TASKS_PATH

Sheet Calls per Process
A1: Onshape API calls by business process
A2: Counts are per unit named in Scope. Rows shaded yellow are PER PART (or per drawing / per task). 'Cold' = nothing in the 5-minute element/document cache (the first part of a run); 'Warm' = those lookups already cached (every subsequent part).
A4: Business process | B4: Trigger | C4: Scope | D4: Ref | E4: API call | F4: Cold cache | G4: Warm cache | H4: Range | I4: Notes
A5: Open the PLM panel | B5: Onshape right panel opens on a part | C5: PER PART, per open | D5: A3 | E5: GET element | F5: 1 | G5: 0 | I5: Cached for 5 minutes, so only the first part looked at in a tab pays for it.
A6: Open the PLM panel | B6: Onshape right panel opens on a part | C6: PER PART, per open | D6: A8 | E6: GET part metadata | F6: 1 | G6: 1 | I6: The mirror read. Never cached — the panel must show what Onshape holds now.
A7: Open the PLM panel | B7: Onshape right panel opens on a part | C7: PER PART, per open | D7: A9 | E7: POST part metadata | F7: 0 | G7: 0 | H7: 0–1 | I7: Only when a mapped value differs. A settled part costs nothing.
A8: Enrol a part (Sync to PLM) | B8: Panel → Sync to PLM | C8: PER PART | D8: A3 | E8: GET element | F8: 1 | G8: 0 | I8: Refuses a drawing or the wrong element type before anything is written.
A9: Enrol a part (Sync to PLM) | B9: Panel → Sync to PLM | C9: PER PART | D9: A8 | E9: GET part metadata | F9: 1 | G9: 1
A10: Enrol a part (Sync to PLM) | B10: Panel → Sync to PLM | C10: PER PART | D10: A9 | E10: POST part metadata | F10: 0 | G10: 0 | H10: 0–1 | I10: Writes the PLM number back on first enrolment, then only on a real difference.
A11: Part changed in Onshape | B11: Onshape metadata webhook | C11: PER PART | D11: A6 | E11: GET element parts | F11: 0 | G11: 0 | H11: 0–1 | I11: Only when the event names no part id and the part has to be resolved.
A12: Part changed in Onshape | B12: Onshape metadata webhook | C12: PER PART | D12: A3 | E12: GET element | F12: 1 | G12: 0
A13: Part changed in Onshape | B13: Onshape metadata webhook | C13: PER PART | D13: A8 | E13: GET part metadata | F13: 1 | G13: 1
A14: Part changed in Onshape | B14: Onshape metadata webhook | C14: PER PART | D14: A9 | E14: POST part metadata | F14: 0 | G14: 0 | H14: 0–1 | I14: Suppressed for PLM's own writes, or the echo would loop.
A15: Push PLM fields to Onshape | B15: Part page → Save | C15: PER PART | D15: A9 | E15: POST part metadata | F15: 1 | G15: 1 | I15: Only the properties that actually differ are sent.
A16: Import from Assembly — each row | B16: Import → Import selected | C16: PER PART | D16: A3 | E16: GET element | F16: 1 | G16: 0 | I16: Warm for every row after the first in the same tab.
A17: Import from Assembly — each row | B17: Import → Import selected | C17: PER PART | D17: A8 | E17: GET part metadata | F17: 1 | G17: 1
A18: Import from Assembly — each row | B18: Import → Import selected | C18: PER PART | D18: A9 | E18: POST part metadata | F18: 0 | G18: 0 | H18: 0–1
A19: Re-sync all from Onshape | B19: Dashboard → Re-sync | C19: PER PART | D19: A3 | E19: GET element | F19: 1 | G19: 0
A20: Re-sync all from Onshape | B20: Dashboard → Re-sync | C20: PER PART | D20: A8 | E20: GET part metadata | F20: 1 | G20: 1
A21: Re-sync all from Onshape | B21: Dashboard → Re-sync | C21: PER PART | D21: A9 | E21: POST part metadata | F21: 0 | G21: 0 | H21: 0–1
A22: Part released (revision) | B22: Release takeover, per part in the package | C22: PER PART | D22: A3 | E22: GET element | F22: 1 | G22: 0
A23: Part released (revision) | B23: Release takeover, per part in the package | C23: PER PART | D23: A8 | E23: GET part metadata | F23: 1 | G23: 1 | I23: Reads the revision Onshape assigned, and snapshots the iteration.
A24: Part released (revision) | B24: Release takeover, per part in the package | C24: PER PART | D24: A9 | E24: POST part metadata | F24: 0 | G24: 0 | H24: 0–1
A25: Drawing captured with a release | B25: Release takeover / drawing refresh | C25: PER DRAWING | D25: A16 | E25: POST drawing translation | F25: 1 | G25: 1 | I25: One PDF render per drawing sheet in the package.
A26: Drawing captured with a release | B26: Release takeover / drawing refresh | C26: PER DRAWING | D26: A14 | E26: GET translation | F26: 1 | G26: 1 | H26: 1–7 | I26: Polled on a 3s/5s/10s/20s/25s/25s backoff until the render finishes.
A27: Drawing captured with a release | B27: Release takeover / drawing refresh | C27: PER DRAWING | D27: A15 | E27: GET external data | F27: 1 | G27: 1
A28: Show a part thumbnail | B28: A part tile renders | C28: PER PART, per open | D28: A10 | E28: GET shaded view | F28: 1 | G28: 0 | H28: 0–1 | I28: Held 7 days in MongoDB; a failed render is not retried for an hour.
A29: Show mass properties | B29: Part page → Mass properties | C29: PER PART, per open | D29: A11 | E29: GET mass properties | F29: 1 | G29: 1 | I29: The mass is written into PLM's Mass attribute as a side effect.
A30: Export a part — STL / Parasolid | B30: Part page → Export | C30: PER PART, per export | D30: A12 | E30: GET part export | F30: 1 | G30: 1 | I30: Streamed straight back; no translation job.
A31: Export a part — STEP / IGES / 3MF | B31: Part page → Export | C31: PER PART, per export | D31: A13 | E31: POST translation | F31: 1 | G31: 1
A32: Export a part — STEP / IGES / 3MF | B32: Part page → Export | C32: PER PART, per export | D32: A14 | E32: GET translation | F32: 1 | G32: 1 | H32: 1–7 | I32: Same backoff as a drawing render.
A33: Export a part — STEP / IGES / 3MF | B33: Part page → Export | C33: PER PART, per export | D33: A15 | E33: GET external data | F33: 1 | G33: 1
A34: Delete a part from PLM | B34: Part page → Delete | C34: PER PART | D34: A9 | E34: POST part metadata | F34: 0 | G34: 0 | H34: 0–1 | I34: Clears the PLM number in Onshape, when one was written.
A35: Task moved on the board | B35: Drag a card between columns | C35: PER TASK | D35: A29 | E35: GET task | F35: 1 | G35: 1 | I35: Read first, so the transition offered is the one the task actually has.
A36: Task moved on the board | B36: Drag a card between columns | C36: PER TASK | D36: A30 | E36: POST task transition | F36: 0 | G36: 0 | H36: 0–1 | I36: Resolved / Rejected only. Onshape's task workflow has no in-progress state.
A37: Task moved on the board | B37: Drag a card between columns | C37: PER TASK | D37: A31 | E37: POST task | F37: 0 | G37: 0 | H37: 0–1 | I37: In Progress and Open are a write to the 'Task State' PROPERTY, not a transition.
A38: Comment on a task from PLM | B38: Task panel → Comment | C38: PER COMMENT | D38: A29 | E38: GET task | F38: 1 | G38: 1 | I38: Needed to find the workflow's Comment property id.
A39: Comment on a task from PLM | B39: Task panel → Comment | C39: PER COMMENT | D39: A31 | E39: POST task | F39: 1 | G39: 1 | I39: A comment IS a property write. There is no comment endpoint for a task.
A40: Edit a task in PLM | B40: Task panel → Save | C40: PER TASK | D40: A31 | E40: POST task | F40: 1 | G40: 1
A41: Remove a task in Onshape | B41: Tasks → Remove in Onshape | C41: PER TASK | D41: A29 | E41: GET task | F41: 1 | G41: 1 | I41: Re-read, so 'deletable' and the discard transition are current rather than stale.
...

Sheet Calls per Process Summary
A1: Total Onshape calls per process
A2: Totals are summed live from the 'Calls per Process' sheet — edit a count there and these update. Per-unit processes are listed first. (Figures compute when Excel opens the file.)
A4: Business process | B4: Scope | C4: Calls — cold cache | D4: Calls — warm cache
A5: Per-unit processes (the ones that scale with your data)
A6: Open the PLM panel | B6: PER PART, per open | C6: =SUMIFS('Calls per Process'!$F$5:$F$70,'Calls per Process'!$A$5:$A$70,$A6) | D6: =SUMIFS('Calls per Process'!$G$5:$G$70,'Calls per Process'!$A$5:$A$70,$A6)
A7: Enrol a part (Sync to PLM) | B7: PER PART | C7: =SUMIFS('Calls per Process'!$F$5:$F$70,'Calls per Process'!$A$5:$A$70,$A7) | D7: =SUMIFS('Calls per Process'!$G$5:$G$70,'Calls per Process'!$A$5:$A$70,$A7)
A8: Part changed in Onshape | B8: PER PART | C8: =SUMIFS('Calls per Process'!$F$5:$F$70,'Calls per Process'!$A$5:$A$70,$A8) | D8: =SUMIFS('Calls per Process'!$G$5:$G$70,'Calls per Process'!$A$5:$A$70,$A8)
A9: Push PLM fields to Onshape | B9: PER PART | C9: =SUMIFS('Calls per Process'!$F$5:$F$70,'Calls per Process'!$A$5:$A$70,$A9) | D9: =SUMIFS('Calls per Process'!$G$5:$G$70,'Calls per Process'!$A$5:$A$70,$A9)
A10: Import from Assembly — each row | B10: PER PART | C10: =SUMIFS('Calls per Process'!$F$5:$F$70,'Calls per Process'!$A$5:$A$70,$A10) | D10: =SUMIFS('Calls per Process'!$G$5:$G$70,'Calls per Process'!$A$5:$A$70,$A10)
A11: Re-sync all from Onshape | B11: PER PART | C11: =SUMIFS('Calls per Process'!$F$5:$F$70,'Calls per Process'!$A$5:$A$70,$A11) | D11: =SUMIFS('Calls per Process'!$G$5:$G$70,'Calls per Process'!$A$5:$A$70,$A11)
A12: Part released (revision) | B12: PER PART | C12: =SUMIFS('Calls per Process'!$F$5:$F$70,'Calls per Process'!$A$5:$A$70,$A12) | D12: =SUMIFS('Calls per Process'!$G$5:$G$70,'Calls per Process'!$A$5:$A$70,$A12)
A13: Drawing captured with a release | B13: PER DRAWING | C13: =SUMIFS('Calls per Process'!$F$5:$F$70,'Calls per Process'!$A$5:$A$70,$A13) | D13: =SUMIFS('Calls per Process'!$G$5:$G$70,'Calls per Process'!$A$5:$A$70,$A13)
A14: Show a part thumbnail | B14: PER PART, per open | C14: =SUMIFS('Calls per Process'!$F$5:$F$70,'Calls per Process'!$A$5:$A$70,$A14) | D14: =SUMIFS('Calls per Process'!$G$5:$G$70,'Calls per Process'!$A$5:$A$70,$A14)
A15: Show mass properties | B15: PER PART, per open | C15: =SUMIFS('Calls per Process'!$F$5:$F$70,'Calls per Process'!$A$5:$A$70,$A15) | D15: =SUMIFS('Calls per Process'!$G$5:$G$70,'Calls per Process'!$A$5:$A$70,$A15)
A16: Export a part — STL / Parasolid | B16: PER PART, per export | C16: =SUMIFS('Calls per Process'!$F$5:$F$70,'Calls per Process'!$A$5:$A$70,$A16) | D16: =SUMIFS('Calls per Process'!$G$5:$G$70,'Calls per Process'!$A$5:$A$70,$A16)
A17: Export a part — STEP / IGES / 3MF | B17: PER PART, per export | C17: =SUMIFS('Calls per Process'!$F$5:$F$70,'Calls per Process'!$A$5:$A$70,$A17) | D17: =SUMIFS('Calls per Process'!$G$5:$G$70,'Calls per Process'!$A$5:$A$70,$A17)
... A22: Remove a task in Onshape | B22: PER TASK | C22: =SUMIFS('Calls per Process'!$F$5:$F$70,'Calls per Process'!$A$5:$A$70,$A22) | D22: =SUMIFS('Calls per Process'!$G$5:$G$70,'Calls per Process'!$A$5:$A$70,$A22)
A23: Per-enterprise, per-assembly, per-release and per-user processes
A24: Connect Onshape account | B24: Per user (one-off) | C24: =SUMIFS('Calls per Process'!$F$5:$F$70,'Calls per Process'!$A$5:$A$70,$A24) | D24: =SUMIFS('Calls per Process'!$G$5:$G$70,'Calls per Process'!$A$5:$A$70,$A24)
A25: Property discovery | B25: Per enterprise (on demand) | C25: =SUMIFS('Calls per Process'!$F$5:$F$70,'Calls per Process'!$A$5:$A$70,$A25) | D25: =SUMIFS('Calls per Process'!$G$5:$G$70,'Calls per Process'!$A$5:$A$70,$A25)
A26: Register webhook | B26: Per enterprise (one-off) | C26: =SUMIFS('Calls per Process'!$F$5:$F$70,'Calls per Process'!$A$5:$A$70,$A26) | D26: =SUMIFS('Calls per Process'!$G$5:$G$70,'Calls per Process'!$A$5:$A$70,$A26)
A27: Import from Assembly — setup | B27: Per assembly | C27: =SUMIFS('Calls per Process'!$F$5:$F$70,'Calls per Process'!$A$5:$A$70,$A27) | D27: =SUMIFS('Calls per Process'!$G$5:$G$70,'Calls per Process'!$A$5:$A$70,$A27)
A28: Release raised in Onshape | B28: Per release | C28: =SUMIFS('Calls per Process'!$F$5:$F$70,'Calls per Process'!$A$5:$A$70,$A28) | D28: =SUMIFS('Calls per Process'!$G$5:$G$70,'Calls per Process'!$A$5:$A$70,$A28)
A29: Release decided in PLM | B29: Per release | C29: =SUMIFS('Calls per Process'!$F$5:$F$70,'Calls per Process'!$A$5:$A$70,$A29) | D29: =SUMIFS('Calls per Process'!$G$5:$G$70,'Calls per Process'!$A$5:$A$70,$A29)
A30: Release raised from PLM | B30: Per release | C30: =SUMIFS('Calls per Process'!$F$5:$F$70,'Calls per Process'!$A$5:$A$70,$A30) | D30: =SUMIFS('Calls per Process'!$G$5:$G$70,'Calls per Process'!$A$5:$A$70,$A30)
A31: Drawing refresh after release | B31: Per release, per attempt | C31: =SUMIFS('Calls per Process'!$F$5:$F$70,'Calls per Process'!$A$5:$A$70,$A31) | D31: =SUMIFS('Calls per Process'!$G$5:$G$70,'Calls per Process'!$A$5:$A$70,$A31)
A32: Task sync from Onshape | B32: Per enterprise (per sync) | C32: =SUMIFS('Calls per Process'!$F$5:$F$70,'Calls per Process'!$A$5:$A$70,$A32) | D32: =SUMIFS('Calls per Process'!$G$5:$G$70,'Calls per Process'!$A$5:$A$70,$A32)
A33: Processes that cost no Onshape calls at all
A34: View a product BOM | B34: Per view | C34: =SUMIFS('Calls per Process'!$F$5:$F$70,'Calls per Process'!$A$5:$A$70,$A34) | D34: =SUMIFS('Calls per Process'!$G$5:$G$70,'Calls per Process'!$A$5:$A$70,$A34)
A35: Tasks shown against a part | B35: Per view | C35: =SUMIFS('Calls per Process'!$F$5:$F$70,'Calls per Process'!$A$5:$A$70,$A35) | D35: =SUMIFS('Calls per Process'!$G$5:$G$70,'Calls per Process'!$A$5:$A$70,$A35)
A36: Dashboard, search and reports | B36: Per view | C36: =SUMIFS('Calls per Process'!$F$5:$F$70,'Calls per Process'!$A$5:$A$70,$A36) | D36: =SUMIFS('Calls per Process'!$G$5:$G$70,'Calls per Process'!$A$5:$A$70,$A36)
A38: Worked examples
A39: First enrolment of a part (cold cache) | B39: One part | C39: =C7 | D39: =C7 | E39: Everything unread: the element lookup is paid for.
A40: Another part in the same tab (warm cache) | B40: One part | C40: =D7 | D40: =D7 | E40: The element and document lookups are already cached.
A41: Import a 40-row assembly | B41: One assembly, 40 parts | C41: =C27+C10+39*D10 | D41: =D27+40*D10 | E41: Setup once, then one row cold and the other 39 warm. The BOM itself is a single call however deep the tree.
A42: Open the panel and show a thumbnail | B42: One part, first view | C42: =C6+C14 | D42: =D6+D14 | E42: The thumbnail is then free for 7 days.
A43: Sync 30 tasks | B43: One sync, 30 tasks | C43: =C32+29 | D43: =D32+29 | E43: Two list calls plus one read per task — the read is what makes a task actionable.
A45: Source: src/lib/onshape/live-client.ts, src/lib/sync.ts, src/lib/release.ts, src/lib/tasks.ts, src/lib/bom-import.ts and the API routes under src/app/api. Endpoint facts cross-checked against Onshape's OpenAPI definition and a live tenant — see docs/ONSHAPE-INTEGRATION-SPEC.md.
